[2023-09-15T10:20:18.225+0000] {taskinstance.py:1125} INFO - Dependencies all met for dep_context=non-requeueable deps ti=<TaskInstance: cinlok4.insert_into_transactions scheduled__2023-09-15T05:00:00+00:00 [queued]>
[2023-09-15T10:20:18.769+0000] {taskinstance.py:1125} INFO - Dependencies all met for dep_context=requeueable deps ti=<TaskInstance: cinlok4.insert_into_transactions scheduled__2023-09-15T05:00:00+00:00 [queued]>
[2023-09-15T10:20:18.771+0000] {taskinstance.py:1331} INFO - Starting attempt 2 of 2
[2023-09-15T10:20:18.825+0000] {taskinstance.py:1350} INFO - Executing <Task(GenericTransfer): insert_into_transactions> on 2023-09-15 05:00:00+00:00
[2023-09-15T10:20:18.839+0000] {standard_task_runner.py:57} INFO - Started process 2902 to run task
[2023-09-15T10:20:18.853+0000] {standard_task_runner.py:84} INFO - Running: ['***', 'tasks', 'run', 'cinlok4', 'insert_into_transactions', 'scheduled__2023-09-15T05:00:00+00:00', '--job-id', '15', '--raw', '--subdir', 'DAGS_FOLDER/transactions.py', '--cfg-path', '/tmp/tmp8qix6bic']
[2023-09-15T10:20:18.859+0000] {standard_task_runner.py:85} INFO - Job 15: Subtask insert_into_transactions
[2023-09-15T10:20:18.987+0000] {task_command.py:410} INFO - Running <TaskInstance: cinlok4.insert_into_transactions scheduled__2023-09-15T05:00:00+00:00 [running]> on host 808631ad8fb6
[2023-09-15T10:20:19.315+0000] {taskinstance.py:1570} INFO - Exporting env vars: AIRFLOW_CTX_DAG_OWNER='Aldinoharyo' AIRFLOW_CTX_DAG_ID='cinlok4' AIRFLOW_CTX_TASK_ID='insert_into_transactions' AIRFLOW_CTX_EXECUTION_DATE='2023-09-15T05:00:00+00:00' AIRFLOW_CTX_TRY_NUMBER='2' AIRFLOW_CTX_DAG_RUN_ID='scheduled__2023-09-15T05:00:00+00:00'
[2023-09-15T10:20:19.357+0000] {taskinstance.py:1847} ERROR - Task failed with exception
Traceback (most recent call last):
  File "/home/airflow/.local/lib/python3.7/site-packages/airflow/operators/generic_transfer.py", line 74, in execute
    source_hook = BaseHook.get_hook(self.source_conn_id)
  File "/home/airflow/.local/lib/python3.7/site-packages/airflow/hooks/base.py", line 84, in get_hook
    connection = cls.get_connection(conn_id)
  File "/home/airflow/.local/lib/python3.7/site-packages/airflow/hooks/base.py", line 72, in get_connection
    conn = Connection.get_connection_from_secrets(conn_id)
  File "/home/airflow/.local/lib/python3.7/site-packages/airflow/models/connection.py", line 434, in get_connection_from_secrets
    raise AirflowNotFoundException(f"The conn_id `{conn_id}` isn't defined")
airflow.exceptions.AirflowNotFoundException: The conn_id `postgres` isn't defined
[2023-09-15T10:20:19.366+0000] {taskinstance.py:1373} INFO - Marking task as FAILED. dag_id=cinlok4, task_id=insert_into_transactions, execution_date=20230915T050000, start_date=20230915T102018, end_date=20230915T102019
[2023-09-15T10:20:19.397+0000] {standard_task_runner.py:109} ERROR - Failed to execute job 15 for task insert_into_transactions (The conn_id `postgres` isn't defined; 2902)
[2023-09-15T10:20:19.428+0000] {local_task_job_runner.py:232} INFO - Task exited with return code 1
[2023-09-15T10:20:19.478+0000] {taskinstance.py:2674} INFO - 0 downstream tasks scheduled from follow-on schedule check
